<?xml version='1.0' encoding='UTF-8'?>
<robot name="jedy">
  <link name="base_link">
  </link>
  <joint name="pseudo_base_joint" type="fixed" >
    <limit effort="0" velocity="0" lower="0" upper="0"/>
    <parent link="base_link"/>
    <child link="real_base_link"/>
    <axis xyz="0. 0. 0."/>
    <origin xyz="0 0 0" rpy="1.5707926535897931 0 1.5707926535897931"/>
  </joint>
  <link name="real_base_link">
    <inertial>
      <origin xyz="-0.000351195235755456 -0.00810559992797557 -0.00714910691571756" rpy="0.0 -0.0 0.0"/>
      <mass value="0.642084743261537"/>
      <inertia ixx="0.000162581139421146" ixy="5.0286786144231e-07" ixz="-9.48818029464138e-07" iyy="0.00024560311724061" iyz="-4.58171534930513e-07" izz="0.000278850372812181"/>
    </inertial>
    <visual>
      <geometry>
        <mesh filename="package://jedy_description/meshes/base_link.dae"/>
      </geometry>
      <material name=""/>
      <origin xyz="0.0 0.0 0.0" rpy="0.0 -0.0 0.0"/>
    </visual>
    <collision>
      <geometry>
        <mesh filename="package://jedy_description/meshes/base_link.dae"/>
      </geometry>
      <origin xyz="0.0 0.0 0.0" rpy="0.0 -0.0 0.0"/>
    </collision>
  </link>
  <link name="rarm_link0">
    <inertial>
      <origin xyz="0.00750000000000114 0.0511983289893697 -0.0774229781318287" rpy="0.0 -0.0 0.0"/>
      <mass value="0.00775312250160503"/>
      <inertia ixx="4.27540101999966e-07" ixy="-4.58771592464844e-22" ixz="-7.33040243663335e-09" iyy="6.49398350259101e-07" iyz="1.01388737603722e-21" izz="7.15408183770753e-07"/>
    </inertial>
    <visual>
      <geometry>
        <mesh filename="package://jedy_description/meshes/rarm_link0.dae"/>
      </geometry>
      <material name=""/>
      <origin xyz="0.00750000000000109 0.0504999999999999 -0.0685000000000001" rpy="1.57079632679489 1.986959066873071e-15 1.57079632679489"/>
    </visual>
    <collision>
      <geometry>
        <mesh filename="package://jedy_description/meshes/rarm_link0.dae"/>
      </geometry>
      <origin xyz="0.00750000000000109 0.0504999999999999 -0.0685000000000001" rpy="1.57079632679489 1.986959066873071e-15 1.57079632679489"/>
    </collision>
  </link>
  <link name="rarm_link1">
    <inertial>
      <origin xyz="0.0060726594429343 0.0630174693748998 -0.076278104560333" rpy="0.0 -0.0 0.0"/>
      <mass value="0.0488819579417231"/>
      <inertia ixx="5.3897919395433e-06" ixy="-2.40958659059239e-08" ixz="-1.15959128616825e-08" iyy="6.30201298165015e-06" iyz="-4.77616974109193e-10" izz="6.89791246161299e-06"/>
    </inertial>
    <visual>
      <geometry>
        <mesh filename="package://jedy_description/meshes/rarm_link1.dae"/>
      </geometry>
      <material name=""/>
      <origin xyz="0.00750000000000735 0.0785 -0.0684999999999999" rpy="1.57079632679489 -3.54391442388401e-16 1.5707963267949"/>
    </visual>
    <collision>
      <geometry>
        <mesh filename="package://jedy_description/meshes/rarm_link1.dae"/>
      </geometry>
      <origin xyz="0.00750000000000735 0.0785 -0.0684999999999999" rpy="1.57079632679489 -3.54391442388401e-16 1.5707963267949"/>
    </collision>
  </link>
  <link name="rarm_link2">
    <inertial>
      <origin xyz="-0.013781849714382 0.078576090677525 -0.0510708977208851" rpy="0.0 -0.0 0.0"/>
      <mass value="0.0267722516782373"/>
      <inertia ixx="3.14025785519115e-06" ixy="-2.1054501660018e-08" ixz="1.16767691320589e-08" iyy="2.73993530782118e-06" iyz="3.18816576527695e-09" izz="3.21445108840275e-06"/>
    </inertial>
    <visual>
      <geometry>
        <mesh filename="package://jedy_description/meshes/rarm_link2.dae"/>
      </geometry>
      <material name=""/>
      <origin xyz="0.00750000000001602 0.0784999999999998 -0.0509999999999999" rpy="1.5707963267949 -2.17212264999435e-15 1.57079632679485"/>
    </visual>
    <collision>
      <geometry>
        <mesh filename="package://jedy_description/meshes/rarm_link2.dae"/>
      </geometry>
      <origin xyz="0.00750000000001602 0.0784999999999998 -0.0509999999999999" rpy="1.5707963267949 -2.17212264999435e-15 1.57079632679485"/>
    </collision>
  </link>
  <link name="rarm_link3">
    <inertial>
      <origin xyz="-0.0419797687715683 0.0785695933122011 -0.0231515381895025" rpy="0.0 -0.0 0.0"/>
      <mass value="0.0356190541582585"/>
      <inertia ixx="3.94460755819088e-06" ixy="5.40131440804977e-08" ixz="-3.18560639543114e-09" iyy="4.39573822732425e-06" iyz="1.16768356053738e-08" izz="4.85566182610951e-06"/>
    </inertial>
    <visual>
      <geometry>
        <mesh filename="package://jedy_description/meshes/rarm_link3.dae"/>
      </geometry>
      <material name=""/>
      <origin xyz="0.00750000000000905 0.0785000000000006 -0.0179999999999999" rpy="1.5707963267949 -2.37767691456137e-15 1.57079632679488"/>
    </visual>
    <collision>
      <geometry>
        <mesh filename="package://jedy_description/meshes/rarm_link3.dae"/>
      </geometry>
      <origin xyz="0.00750000000000905 0.0785000000000006 -0.0179999999999999" rpy="1.5707963267949 -2.37767691456137e-15 1.57079632679488"/>
    </collision>
  </link>
  <link name="rarm_link4">
    <inertial>
      <origin xyz="0.0016510438589472 0.0778057578962844 0.0566210301742714" rpy="0.0 -0.0 0.0"/>
      <mass value="0.00736377671410321"/>
      <inertia ixx="6.23026208790114e-07" ixy="4.64911587686377e-09" ixz="-1.21774119934071e-14" iyy="4.1517508351772e-07" iyz="-1.47706067420849e-12" izz="5.58392363215573e-07"/>
    </inertial>
    <visual>
      <geometry>
        <mesh filename="package://jedy_description/meshes/rarm_link4.dae"/>
      </geometry>
      <material name=""/>
      <origin xyz="0.00997906015717234 0.077805399918878 0.0569999999999997" rpy="1.5707963267949 -0.0 1.5707963267949"/>
    </visual>
    <collision>
      <geometry>
        <mesh filename="package://jedy_description/meshes/rarm_link4.dae"/>
      </geometry>
      <origin xyz="0.00997906015717234 0.077805399918878 0.0569999999999997" rpy="1.5707963267949 -0.0 1.5707963267949"/>
    </collision>
  </link>
  <link name="rarm_link5">
    <inertial>
      <origin xyz="-0.000466911885189514 0.0624063256412892 0.0815726594429263" rpy="0.0 -0.0 0.0"/>
      <mass value="0.0488819579417229"/>
      <inertia ixx="6.30201298165013e-06" ixy="-1.80131374142072e-08" ixz="-2.38311555265213e-08" iyy="5.38979193954328e-06" iyz="1.15959128617003e-08" izz="6.89791246161297e-06"/>
    </inertial>
    <visual>
      <geometry>
        <mesh filename="package://jedy_description/meshes/rarm_link5.dae"/>
      </geometry>
      <material name=""/>
      <origin xyz="0.00997906015717333 0.077805399918878 0.0829999999999996" rpy="1.5707963267949 -0.0 1.57079632679489"/>
    </visual>
    <collision>
      <geometry>
        <mesh filename="package://jedy_description/meshes/rarm_link5.dae"/>
      </geometry>
      <origin xyz="0.00997906015717333 0.077805399918878 0.0829999999999996" rpy="1.5707963267949 -0.0 1.57079632679489"/>
    </collision>
  </link>
  <link name="rarm_link6">
    <inertial>
      <origin xyz="-0.0330277428947269 0.0768233052251458 0.100619882815324" rpy="0.0 -0.0 0.0"/>
      <mass value="0.0333926389608614"/>
      <inertia ixx="3.30636322891007e-06" ixy="2.99884795330491e-07" ixz="1.36097064864093e-08" iyy="3.77315458100189e-06" iyz="2.71887959762946e-08" izz="3.96432574101108e-06"/>
    </inertial>
    <visual>
      <geometry>
        <mesh filename="package://jedy_description/meshes/rarm_link6.dae"/>
      </geometry>
      <material name=""/>
      <origin xyz="0.00997906015717347 0.0778053999188794 0.103999999999997" rpy="1.5707963267949 -3.6845526629748716e-15 1.57079632679492"/>
    </visual>
    <collision>
      <geometry>
        <mesh filename="package://jedy_description/meshes/rarm_link6.dae"/>
      </geometry>
      <origin xyz="0.00997906015717347 0.0778053999188794 0.103999999999997" rpy="1.5707963267949 -3.6845526629748716e-15 1.57079632679492"/>
    </collision>
  </link>
  <link name="rarm_link7">
    <inertial>
      <origin xyz="-0.00575793188359448 0.0909946641170031 0.154628764458567" rpy="0.0 -0.0 0.0"/>
      <mass value="0.00895541725275716"/>
      <inertia ixx="1.56881539249378e-06" ixy="2.90079247027908e-07" ixz="1.36850293455652e-12" iyy="4.24237090037039e-07" iyz="5.6685247064795e-13" izz="1.66621992553874e-06"/>
    </inertial>
    <visual>
      <geometry>
        <mesh filename="package://jedy_description/meshes/rarm_link7.dae"/>
      </geometry>
      <material name=""/>
      <origin xyz="0.00997906015717007 0.0895426281771284 0.160302971010996" rpy="1.57079632679491 -4.18415302405635e-15 1.57079632679491"/>
    </visual>
    <collision>
      <geometry>
        <mesh filename="package://jedy_description/meshes/rarm_link7.dae"/>
      </geometry>
      <origin xyz="0.00997906015717007 0.0895426281771284 0.160302971010996" rpy="1.57079632679491 -4.18415302405635e-15 1.57079632679491"/>
    </collision>
  </link>
  <link name="rarm_link8">
    <inertial>
      <origin xyz="-0.00575793188359814 0.064611878473499 0.165977177563427" rpy="0.0 -0.0 0.0"/>
      <mass value="0.00895541725275716"/>
      <inertia ixx="1.56881539249378e-06" ixy="-2.90079247027908e-07" ixz="1.3685029352065e-12" iyy="4.24237090037038e-07" iyz="-5.66852472660774e-13" izz="1.66621992553874e-06"/>
    </inertial>
    <visual>
      <geometry>
        <mesh filename="package://jedy_description/meshes/rarm_link8.dae"/>
      </geometry>
      <material name=""/>
      <origin xyz="0.00997906015716632 0.0660639144133757 0.160302971010998" rpy="1.57079632679488 4.184153024056432e-15 1.57079632679492"/>
    </visual>
    <collision>
      <geometry>
        <mesh filename="package://jedy_description/meshes/rarm_link8.dae"/>
      </geometry>
      <origin xyz="0.00997906015716632 0.0660639144133757 0.160302971010998" rpy="1.57079632679488 4.184153024056432e-15 1.57079632679492"/>
    </collision>
  </link>
  <link name="larm_link0">
    <inertial>
      <origin xyz="0.00750000000000804 0.0498016710106214 0.0774229781318285" rpy="0.0 -0.0 0.0"/>
      <mass value="0.00775312250160503"/>
      <inertia ixx="4.27540101999965e-07" ixy="3.76136064915158e-22" ixz="7.33040243663328e-09" iyy="6.49398350259101e-07" iyz="-9.82862838779766e-22" izz="7.15408183770753e-07"/>
    </inertial>
    <visual>
      <geometry>
        <mesh filename="package://jedy_description/meshes/larm_link0.dae"/>
      </geometry>
      <material name=""/>
      <origin xyz="0.00750000000000825 0.0505000000000001 0.0684999999999997" rpy="-1.57079632679489 -2.08412807937063e-15 -1.5707963267949"/>
    </visual>
    <collision>
      <geometry>
        <mesh filename="package://jedy_description/meshes/larm_link0.dae"/>
      </geometry>
      <origin xyz="0.00750000000000825 0.0505000000000001 0.0684999999999997" rpy="-1.57079632679489 -2.08412807937063e-15 -1.5707963267949"/>
    </collision>
  </link>
  <link name="larm_link1">
    <inertial>
      <origin xyz="0.00742734055676281 -0.0939825306250985 -0.0607218954396666" rpy="0.0 -0.0 0.0"/>
      <mass value="0.0488819579417233"/>
      <inertia ixx="5.38979193954333e-06" ixy="-2.40958659059249e-08" ixz="1.15959128616777e-08" iyy="6.30201298165015e-06" iyz="4.77616974083206e-10" izz="6.89791246161303e-06"/>
    </inertial>
    <visual>
      <geometry>
        <mesh filename="package://jedy_description/meshes/larm_link1.dae"/>
      </geometry>
      <material name=""/>
      <origin xyz="0.00750000000000863 -0.0785000000000002 -0.0684999999999996" rpy="1.5707963267949 3.62060067618232e-15 1.5707963267949"/>
    </visual>
    <collision>
      <geometry>
        <mesh filename="package://jedy_description/meshes/larm_link1.dae"/>
      </geometry>
      <origin xyz="0.00750000000000863 -0.0785000000000002 -0.0684999999999996" rpy="1.5707963267949 3.62060067618232e-15 1.5707963267949"/>
    </collision>
  </link>
  <link name="larm_link2">
    <inertial>
      <origin xyz="-0.0137818497143928 -0.0785760906775208 -0.0509291022791145" rpy="0.0 -0.0 0.0"/>
      <mass value="0.0267722516782377"/>
      <inertia ixx="3.14025785519116e-06" ixy="2.10545016600191e-08" ixz="1.16767691320627e-08" iyy="2.73993530782123e-06" iyz="-3.18816576528393e-09" izz="3.21445108840279e-06"/>
    </inertial>
    <visual>
      <geometry>
        <mesh filename="package://jedy_description/meshes/larm_link2.dae"/>
      </geometry>
      <material name=""/>
      <origin xyz="0.00750000000000532 -0.0785 -0.0509999999999999" rpy="1.5707963267949 2.1371793224098e-15 1.57079632679491"/>
    </visual>
    <collision>
      <geometry>
        <mesh filename="package://jedy_description/meshes/larm_link2.dae"/>
      </geometry>
      <origin xyz="0.00750000000000532 -0.0785 -0.0509999999999999" rpy="1.5707963267949 2.1371793224098e-15 1.57079632679491"/>
    </collision>
  </link>
  <link name="larm_link3">
    <inertial>
      <origin xyz="-0.0419797687715708 -0.0785572640137325 -0.012692437828887" rpy="0.0 -0.0 0.0"/>
      <mass value="0.035619054158259"/>
      <inertia ixx="3.94460755819094e-06" ixy="-4.07455626958971e-08" ixz="-3.18560639540328e-09" iyy="4.39573822732428e-06" iyz="-1.1676718625715e-08" izz="4.85566182610956e-06"/>
    </inertial>
    <visual>
      <geometry>
        <mesh filename="package://jedy_description/meshes/larm_link3.dae"/>
      </geometry>
      <material name=""/>
      <origin xyz="0.00750000000000711 -0.0785000000000005 -0.0180000000000003" rpy="1.5707963267949 2.37767691456137e-15 1.57079632679491"/>
    </visual>
    <collision>
      <geometry>
        <mesh filename="package://jedy_description/meshes/larm_link3.dae"/>
      </geometry>
      <origin xyz="0.00750000000000711 -0.0785000000000005 -0.0180000000000003" rpy="1.5707963267949 2.37767691456137e-15 1.57079632679491"/>
    </collision>
  </link>
  <link name="larm_link4">
    <inertial>
      <origin xyz="0.00165104385894364 -0.0778057578962786 0.0573789698257278" rpy="0.0 -0.0 0.0"/>
      <mass value="0.0073637767141032"/>
      <inertia ixx="6.23026208790113e-07" ixy="-4.64911587686424e-09" ixz="-1.21774114868373e-14" iyy="4.15175083517719e-07" iyz="1.47706067387539e-12" izz="5.58392363215573e-07"/>
    </inertial>
    <visual>
      <geometry>
        <mesh filename="package://jedy_description/meshes/larm_link4.dae"/>
      </geometry>
      <material name=""/>
      <origin xyz="0.00997906015716914 -0.077805399918878 0.0569999999999994" rpy="1.5707963267949 2.109502468254791e-15 1.57079632679489"/>
    </visual>
    <collision>
      <geometry>
        <mesh filename="package://jedy_description/meshes/larm_link4.dae"/>
      </geometry>
      <origin xyz="0.00997906015716914 -0.077805399918878 0.0569999999999994" rpy="1.5707963267949 2.109502468254791e-15 1.57079632679489"/>
    </collision>
  </link>
  <link name="larm_link5">
    <inertial>
      <origin xyz="-0.000466911885188184 -0.0932044741964692 0.083072659443248" rpy="0.0 -0.0 0.0"/>
      <mass value="0.0488819579417233"/>
      <inertia ixx="6.30201298165017e-06" ixy="-1.80131374141397e-08" ixz="-2.38311555265008e-08" iyy="5.38979193954332e-06" iyz="1.15959128617046e-08" izz="6.89791246161298e-06"/>
    </inertial>
    <visual>
      <geometry>
        <mesh filename="package://jedy_description/meshes/larm_link5.dae"/>
      </geometry>
      <material name=""/>
      <origin xyz="0.00997906015717186 -0.0778053999188787 0.0830000000000017" rpy="1.5707963267949 -6.64973364763795e-15 1.5707963267949"/>
    </visual>
    <collision>
      <geometry>
        <mesh filename="package://jedy_description/meshes/larm_link5.dae"/>
      </geometry>
      <origin xyz="0.00997906015717186 -0.0778053999188787 0.0830000000000017" rpy="1.5707963267949 -6.64973364763795e-15 1.5707963267949"/>
    </collision>
  </link>
  <link name="larm_link6">
    <inertial>
      <origin xyz="-0.033027742894731 -0.0777001820412116 0.107380117184671" rpy="0.0 -0.0 0.0"/>
      <mass value="0.0333926389608612"/>
      <inertia ixx="3.30636322891005e-06" ixy="-2.99884795330496e-07" ixz="1.36097064863934e-08" iyy="3.77315458100187e-06" iyz="-1.25309536168303e-08" izz="3.96432574101107e-06"/>
    </inertial>
    <visual>
      <geometry>
        <mesh filename="package://jedy_description/meshes/larm_link6.dae"/>
      </geometry>
      <material name=""/>
      <origin xyz="0.00997906015716958 -0.0778053999188793 0.103999999999997" rpy="1.5707963267949 3.684552662974871e-15 1.57079632679487"/>
    </visual>
    <collision>
      <geometry>
        <mesh filename="package://jedy_description/meshes/larm_link6.dae"/>
      </geometry>
      <origin xyz="0.00997906015716958 -0.0778053999188793 0.103999999999997" rpy="1.5707963267949 3.684552662974871e-15 1.57079632679487"/>
    </collision>
  </link>
  <link name="larm_link7">
    <inertial>
      <origin xyz="-0.00575793188358857 -0.0909946641169996 0.165977177563423" rpy="0.0 -0.0 0.0"/>
      <mass value="0.00895541725275716"/>
      <inertia ixx="1.56881539249378e-06" ixy="-2.90079247027908e-07" ixz="1.3685029341339e-12" iyy="4.24237090037038e-07" iyz="-5.66852473175791e-13" izz="1.66621992553874e-06"/>
    </inertial>
    <visual>
      <geometry>
        <mesh filename="package://jedy_description/meshes/larm_link7.dae"/>
      </geometry>
      <material name=""/>
      <origin xyz="0.00997906015717492 -0.089542628177131 0.160302971010997" rpy="1.57079632679489 4.1841530240560895e-15 1.57079632679488"/>
    </visual>
    <collision>
      <geometry>
        <mesh filename="package://jedy_description/meshes/larm_link7.dae"/>
      </geometry>
      <origin xyz="0.00997906015717492 -0.089542628177131 0.160302971010997" rpy="1.57079632679489 4.1841530240560895e-15 1.57079632679488"/>
    </collision>
  </link>
  <link name="larm_link8">
    <inertial>
      <origin xyz="-0.00575793188358593 -0.0646118784734955 0.154628764458567" rpy="0.0 -0.0 0.0"/>
      <mass value="0.00895541725275716"/>
      <inertia ixx="1.56881539249378e-06" ixy="2.90079247027908e-07" ixz="1.36850293341796e-12" iyy="4.24237090037038e-07" iyz="5.66852471090155e-13" izz="1.66621992553874e-06"/>
    </inertial>
    <visual>
      <geometry>
        <mesh filename="package://jedy_description/meshes/larm_link8.dae"/>
      </geometry>
      <material name=""/>
      <origin xyz="0.00997906015717727 -0.0660639144133791 0.160302971010999" rpy="1.5707963267949 -4.184153024056081e-15 1.57079632679487"/>
    </visual>
    <collision>
      <geometry>
        <mesh filename="package://jedy_description/meshes/larm_link8.dae"/>
      </geometry>
      <origin xyz="0.00997906015717727 -0.0660639144133791 0.160302971010999" rpy="1.5707963267949 -4.184153024056081e-15 1.57079632679487"/>
    </collision>
  </link>
  <link name="head_link0">
    <inertial>
      <origin xyz="0.0287818497143985 7.60906775256067e-05 -0.0859291022791144" rpy="0.0 -0.0 0.0"/>
      <mass value="0.0267722516782374"/>
      <inertia ixx="3.14025785519115e-06" ixy="-2.10545016600164e-08" ixz="-1.16767691320583e-08" iyy="2.7399353078212e-06" iyz="-3.18816576528483e-09" izz="3.21445108840277e-06"/>
    </inertial>
    <visual>
      <geometry>
        <mesh filename="package://jedy_description/meshes/head_link0.dae"/>
      </geometry>
      <material name=""/>
      <origin xyz="0.00749999999999987 -5.38287282543344e-17 -0.086" rpy="1.57079632679491 -1.22464679914727e-16 1.5707963267949"/>
    </visual>
    <collision>
      <geometry>
        <mesh filename="package://jedy_description/meshes/head_link0.dae"/>
      </geometry>
      <origin xyz="0.00749999999999987 -5.38287282543344e-17 -0.086" rpy="1.57079632679491 -1.22464679914727e-16 1.5707963267949"/>
    </collision>
  </link>
  <link name="head_link1">
    <inertial>
      <origin xyz="0.0563071474852643 0.00458336726096902 -0.118986177954781" rpy="0.0 -0.0 0.0"/>
      <mass value="0.184305345878305"/>
      <inertia ixx="2.6255357924015e-05" ixy="3.04375090051604e-08" ixz="-4.80511209762755e-08" iyy="2.79766917910753e-05" iyz="-2.78258729227929e-08" izz="4.63202146600336e-05"/>
    </inertial>
    <visual>
      <geometry>
        <mesh filename="package://jedy_description/meshes/head_link1.dae"/>
      </geometry>
      <material name=""/>
      <origin xyz="0.00749999999999211 1.66972953365245e-15 -0.119" rpy="1.57079632679491 -2.044002511535201e-16 1.57079632679492"/>
    </visual>
    <collision>
      <geometry>
        <mesh filename="package://jedy_description/meshes/head_link1.dae"/>
      </geometry>
      <origin xyz="0.00749999999999211 1.66972953365245e-15 -0.119" rpy="1.57079632679491 -2.044002511535201e-16 1.57079632679492"/>
    </collision>
  </link>
  <link name="front_right_wheel_link">
    <inertial>
      <origin xyz="0.0344932842136683 0.0970000970916309 -0.0435000024416005" rpy="0.0 -0.0 0.0"/>
      <mass value="0.0620356799852319"/>
      <inertia ixx="1.17891072454946e-05" ixy="-4.41939757993746e-11" ixz="2.8155029764713e-12" iyy="9.70723532361731e-06" iyz="2.3526216007568e-12" izz="9.707219297398e-06"/>
    </inertial>
    <visual>
      <geometry>
        <mesh filename="package://jedy_description/meshes/front_right_wheel_link.dae"/>
      </geometry>
      <material name=""/>
      <origin xyz="0.0505000000000009 0.097 -0.0434999999999994" rpy="0.0 -0.0 0.0"/>
    </visual>
    <collision>
      <geometry>
        <mesh filename="package://jedy_description/meshes/front_right_wheel_link.dae"/>
      </geometry>
      <origin xyz="0.0505000000000009 0.097 -0.0434999999999994" rpy="0.0 -0.0 0.0"/>
    </collision>
  </link>
  <link name="front_left_wheel_link">
    <inertial>
      <origin xyz="-0.0344932901302818 0.0969999049831629 -0.0435000004047774" rpy="0.0 -0.0 0.0"/>
      <mass value="0.0620331863909222"/>
      <inertia ixx="1.17881307318182e-05" ixy="-4.52960489509934e-11" ixz="2.33278294698924e-12" iyy="9.70649490175883e-06" iyz="3.34165767029261e-12" izz="9.7064772842312e-06"/>
    </inertial>
    <visual>
      <geometry>
        <mesh filename="package://jedy_description/meshes/front_left_wheel_link.dae"/>
      </geometry>
      <material name=""/>
      <origin xyz="-0.0504999999999993 0.0970000000000006 -0.0434999999999985" rpy="0.0 -0.0 0.0"/>
    </visual>
    <collision>
      <geometry>
        <mesh filename="package://jedy_description/meshes/front_left_wheel_link.dae"/>
      </geometry>
      <origin xyz="-0.0504999999999993 0.0970000000000006 -0.0434999999999985" rpy="0.0 -0.0 0.0"/>
    </collision>
  </link>
  <link name="rear_right_wheel_link">
    <inertial>
      <origin xyz="0.0344932842136686 0.0970000970916324 0.0434999975583993" rpy="0.0 -0.0 0.0"/>
      <mass value="0.0620356799852319"/>
      <inertia ixx="1.17891072454946e-05" ixy="-4.41939758006981e-11" ixz="2.81550297072405e-12" iyy="9.70723532361731e-06" iyz="2.35262160013476e-12" izz="9.707219297398e-06"/>
    </inertial>
    <visual>
      <geometry>
        <mesh filename="package://jedy_description/meshes/rear_right_wheel_link.dae"/>
      </geometry>
      <material name=""/>
      <origin xyz="0.0505000000000012 0.0969999999999992 0.0435000000000006" rpy="0.0 -0.0 0.0"/>
    </visual>
    <collision>
      <geometry>
        <mesh filename="package://jedy_description/meshes/rear_right_wheel_link.dae"/>
      </geometry>
      <origin xyz="0.0505000000000012 0.0969999999999992 0.0435000000000006" rpy="0.0 -0.0 0.0"/>
    </collision>
  </link>
  <link name="rear_left_wheel_link">
    <inertial>
      <origin xyz="-0.0344932901302836 0.0969999049831609 0.0434999995952184" rpy="0.0 -0.0 0.0"/>
      <mass value="0.0620331863909222"/>
      <inertia ixx="1.17881307318182e-05" ixy="-4.52960489535212e-11" ixz="2.33278294290793e-12" iyy="9.70649490175883e-06" iyz="3.34165766872427e-12" izz="9.70647728423119e-06"/>
    </inertial>
    <visual>
      <geometry>
        <mesh filename="package://jedy_description/meshes/rear_left_wheel_link.dae"/>
      </geometry>
      <material name=""/>
      <origin xyz="-0.0504999999999999 0.0969999999999994 0.0435000000000005" rpy="0.0 -0.0 0.0"/>
    </visual>
    <collision>
      <geometry>
        <mesh filename="package://jedy_description/meshes/rear_left_wheel_link.dae"/>
      </geometry>
      <origin xyz="-0.0504999999999999 0.0969999999999994 0.0435000000000005" rpy="0.0 -0.0 0.0"/>
    </collision>
  </link>
  <joint name="rarm_joint0" type="revolute">
    <limit effort="0.48" velocity="6.55" lower="-2.35" upper="2.35"/>
    <parent link="real_base_link"/>
    <child link="rarm_link0"/>
    <axis xyz="0. 1. 0."/>
    <origin xyz="-0.0505 0.0685 -0.0075" rpy="-1.5707926535897931 -1.5707926535897931 -0.0015926535897931142"/>
  </joint>
  <joint name="rarm_joint1" type="revolute">
    <limit effort="0.48" velocity="6.55" lower="-2.35" upper="0.52"/>
    <parent link="rarm_link0"/>
    <child link="rarm_link1"/>
    <axis xyz="1. 0. 0."/>
    <origin xyz="0.0 -0.028 0.0" rpy="0.0 -0.0 0.0"/>
  </joint>
  <joint name="rarm_joint2" type="revolute">
    <limit effort="0.48" velocity="6.55" lower="-2.35" upper="2.35"/>
    <parent link="rarm_link1"/>
    <child link="rarm_link2"/>
    <axis xyz="0. 0. 1."/>
    <origin xyz="0.0 0.0 -0.0175" rpy="0.0 -0.0 0.0"/>
  </joint>
  <joint name="rarm_joint3" type="revolute">
    <limit effort="0.48" velocity="6.55" lower="-2.35" upper="2.35"/>
    <parent link="rarm_link2"/>
    <child link="rarm_link3"/>
    <axis xyz="0. 1. 0."/>
    <origin xyz="0.0 0.0 -0.033" rpy="0.0 -0.0 0.0"/>
  </joint>
  <joint name="rarm_joint4" type="revolute">
    <limit effort="0.48" velocity="6.55" lower="-2.35" upper="2.35"/>
    <parent link="rarm_link3"/>
    <child link="rarm_link4"/>
    <axis xyz="0. 0. 1."/>
    <origin xyz="-0.0024791 0.0006946 -0.075" rpy="0.0 -0.0 0.0"/>
  </joint>
  <joint name="rarm_joint5" type="revolute">
    <limit effort="0.48" velocity="6.55" lower="-1.57" upper="1.05"/>
    <parent link="rarm_link4"/>
    <child link="rarm_link5"/>
    <axis xyz="0. 1. 0."/>
    <origin xyz="0.0 0.0 -0.026" rpy="0.0 -0.0 0.0"/>
  </joint>
  <joint name="rarm_joint6" type="revolute">
    <limit effort="0.48" velocity="6.55" lower="-1.57" upper="1.57"/>
    <parent link="rarm_link5"/>
    <child link="rarm_link6"/>
    <axis xyz="1. 0. 0."/>
    <origin xyz="0.0 0.0 -0.021" rpy="0.0 -0.0 0.0"/>
  </joint>
  <joint name="rarm_gripper_joint" type="revolute">
    <limit effort="0.48" velocity="6.55" lower="-1.57" upper="0.5"/>
    <parent link="rarm_link6"/>
    <child link="rarm_link7"/>
    <axis xyz="1. 0. 0."/>
    <origin xyz="0.0 -0.011737 -0.056303" rpy="0.0 -0.0 0.0"/>
  </joint>
  <joint name="rarm_mimic_gripper_joint" type="revolute">
    <limit effort="0.48" velocity="6.55" lower="-0.5" upper="1.57"/>
    <mimic joint="rarm_gripper_joint" multiplier="-1.0" offset="0.0"/>
    <parent link="rarm_link6"/>
    <child link="rarm_link8"/>
    <axis xyz="1. 0. 0."/>
    <origin xyz="0.0 0.011741 -0.056303" rpy="0.0 -0.0 0.0"/>
  </joint>
  <joint name="larm_joint0" type="revolute">
    <limit effort="0.48" velocity="6.55" lower="-2.35" upper="2.35"/>
    <parent link="real_base_link"/>
    <child link="larm_link0"/>
    <axis xyz="0. 1. 0."/>
    <origin xyz="0.0505 0.0685 -0.0075" rpy="-1.5707926535897931 -1.5707926535897931 3.141592653589793"/>
  </joint>
  <joint name="larm_joint1" type="revolute">
    <limit effort="0.48" velocity="6.55" lower="-0.56" upper="2.35"/>
    <parent link="larm_link0"/>
    <child link="larm_link1"/>
    <axis xyz="1. 0. 0."/>
    <origin xyz="0.0 -0.028 0.0" rpy="3.1415853071795867 -0.0 0.0"/>
  </joint>
  <joint name="larm_joint2" type="revolute">
    <limit effort="0.48" velocity="6.55" lower="-2.35" upper="2.35"/>
    <parent link="larm_link1"/>
    <child link="larm_link2"/>
    <axis xyz="0. 0. 1."/>
    <origin xyz="0.0 0.0 -0.0175" rpy="0.0 -0.0 0.0"/>
  </joint>
  <joint name="larm_joint3" type="revolute">
    <limit effort="0.48" velocity="6.55" lower="-2.35" upper="2.35"/>
    <parent link="larm_link2"/>
    <child link="larm_link3"/>
    <axis xyz="0. 1. 0."/>
    <origin xyz="0.0 0.0 -0.033" rpy="0.0 -0.0 0.0"/>
  </joint>
  <joint name="larm_joint4" type="revolute">
    <limit effort="0.48" velocity="6.55" lower="-2.35" upper="2.35"/>
    <parent link="larm_link3"/>
    <child link="larm_link4"/>
    <axis xyz="0. 0. 1."/>
    <origin xyz="-0.0024791 -0.0006946 -0.075" rpy="0.0 -0.0 0.0"/>
  </joint>
  <joint name="larm_joint5" type="revolute">
    <limit effort="0.48" velocity="6.55" lower="-1.57" upper="1.05"/>
    <parent link="larm_link4"/>
    <child link="larm_link5"/>
    <axis xyz="0. 1. 0."/>
    <origin xyz="0.0 0.0 -0.026" rpy="0.0 -0.0 0.0"/>
  </joint>
  <joint name="larm_joint6" type="revolute">
    <limit effort="0.48" velocity="6.55" lower="-1.57" upper="1.57"/>
    <parent link="larm_link5"/>
    <child link="larm_link6"/>
    <axis xyz="1. 0. 0."/>
    <origin xyz="0.0 0.0 -0.021" rpy="0.0 -0.0 0.0"/>
  </joint>
  <joint name="larm_gripper_joint" type="revolute">
    <limit effort="0.48" velocity="6.55" lower="-0.5" upper="1.57"/>
    <parent link="larm_link6"/>
    <child link="larm_link7"/>
    <axis xyz="1. 0. 0."/>
    <origin xyz="0.0 0.011737 -0.056303" rpy="0.0 -0.0 0.0"/>
  </joint>
  <joint name="larm_mimic_gripper_joint" type="revolute">
    <limit effort="0.48" velocity="6.55" lower="-1.57" upper="0.5"/>
    <mimic joint="larm_gripper_joint" multiplier="-1.0" offset="0.0"/>
    <parent link="larm_link6"/>
    <child link="larm_link8"/>
    <axis xyz="1. 0. 0."/>
    <origin xyz="0.0 -0.011741 -0.056303" rpy="0.0 -0.0 0.0"/>
  </joint>
  <joint name="head_joint0" type="revolute">
    <limit effort="0.48" velocity="6.55" lower="-2.35" upper="2.35"/>
    <parent link="real_base_link"/>
    <child link="head_link0"/>
    <axis xyz="0. 0. 1."/>
    <origin xyz="0.0 0.086 -0.0075" rpy="-3.141592653589793 -1.5707926535897931 1.5707926535897931"/>
  </joint>
  <joint name="head_joint1" type="revolute">
    <limit effort="0.48" velocity="6.55" lower="-1.57" upper="1.57"/>
    <parent link="head_link0"/>
    <child link="head_link1"/>
    <axis xyz="0. 1. 0."/>
    <origin xyz="0.0 0.0 0.033" rpy="0.0 -0.0 0.0"/>
  </joint>
  <joint name="front_right_wheel_joint" type="continuous">
    <limit effort="0.48" velocity="6.55"/>
    <parent link="real_base_link"/>
    <child link="front_right_wheel_link"/>
    <axis xyz="1. 0. 0."/>
    <origin xyz="-0.0505 -0.097 0.0435" rpy="0.0 -0.0 0.0"/>
  </joint>
  <joint name="front_left_wheel_joint" type="continuous">
    <limit effort="0.48" velocity="6.55"/>
    <parent link="real_base_link"/>
    <child link="front_left_wheel_link"/>
    <axis xyz="1. 0. 0."/>
    <origin xyz="0.0505 -0.097 0.0435" rpy="0.0 -0.0 0.0"/>
  </joint>
  <joint name="rear_right_wheel_joint" type="continuous">
    <limit effort="0.48" velocity="6.55"/>
    <parent link="real_base_link"/>
    <child link="rear_right_wheel_link"/>
    <axis xyz="1. 0. 0."/>
    <origin xyz="-0.0505 -0.097 -0.0435" rpy="0.0 -0.0 0.0"/>
  </joint>
  <joint name="rear_left_wheel_joint" type="continuous">
    <limit effort="0.48" velocity="6.55"/>
    <parent link="real_base_link"/>
    <child link="rear_left_wheel_link"/>
    <axis xyz="1. 0. 0."/>
    <origin xyz="0.0505 -0.097 -0.0435" rpy="0.0 -0.0 0.0"/>
  </joint>
  <material name="">
    <color rgba="0.75294118 0.75294118 0.75294118 1.        "/>
  </material>
</robot>
